Workbook

Sheet LEGENDA
A1: LEGENDA E GUIDA ALLA LETTURA
A3: 1. GERARCHIA DELLE TIPOLOGIE DOCUMENTALI
A5: Livello | B5: Tipologia | C5: Descrizione | D5: Approvazione | E5: Codice
A6: 1 | B6: Policy | C6: Documento di indirizzo strategico che definisce principi, obiettivi e responsabilità ad alto livello. Stabilisce il 'cosa' e il 'perché'. | D6: Direzione/Organi Apicali | E6: POL
A7: 2 | B7: Processo | C7: Descrizione delle attività interconnesse che trasformano input in output. Definisce il flusso logico e le responsabilità macro. | D7: Direzione/CISO | E7: PRC
A8: 3 | B8: Procedura | C8: Documento che specifica 'chi fa cosa, quando e come'. Dettaglia le modalità operative di attuazione di un processo. | D8: CISO/Responsabili di Area | E8: PRO
A9: 4 | B9: Linea Guida | C9: Raccomandazioni e best practice non vincolanti che orientano le scelte tecniche e operative. | D9: CISO/Comitato Sicurezza | E9: LG)
A10: 5 | B10: Istruzione Operativa | C10: Istruzioni dettagliate step-by-step per l'esecuzione di attività specifiche e ripetibili. | D10: Responsabile Operativo | E10: IO)
A11: 6 | B11: Manuale Operativo | C11: Raccolta organizzata di istruzioni operative e specifiche tecniche per un sistema o servizio. | D11: Responsabile Tecnico | E11: MAN
A12: 7 | B12: Playbook | C12: Documento operativo per la gestione di scenari specifici (es. incident response) con azioni predefinite. | D12: SOC Manager/CSIRT | E12: PLB
A13: 8 | B13: Piano | C13: Documento che descrive obiettivi, attività, risorse e tempistiche per raggiungere un risultato specifico. | D13: CISO/PM | E13: PIA
A14: 9 | B14: Registro | C14: Raccolta strutturata di informazioni da mantenere aggiornate (es. asset, rischi, incidenti). | D14: Asset Owner/CISO | E14: REG
A15: 10 | B15: Report | C15: Documento che presenta risultati di analisi, audit, test o valutazioni. | D15: Funzione competente | E15: REP
A18: 2. ABBREVIAZIONI FONTI NORMATIVE E STANDARD
A20: Abbreviazione | B20: Fonte Completa | C20: Ambito | D20: Cogenza per PA
A21: NIS2 | B21: Direttiva (UE) 2022/2555 - D.Lgs. 138/2024 | C21: Sicurezza reti e sistemi informativi | D21: Obbligatorio per soggetti essenziali/importanti
A22: ACN-DET | B22: Determinazioni ACN (379907/2025, 164179/2025) | C22: Misure sicurezza base e incidenti | D22: Obbligatorio per soggetti NIS
A23: L90/2024 | B23: Legge 28 giugno 2024, n. 90 | C23: Rafforzamento cybersicurezza nazionale | D23: Obbligatorio per PA e soggetti strategici
A24: FNCS | B24: Framework Nazionale Cybersecurity e Data Protection v2.1 (2025) | C24: Gestione rischio cyber | D24: Riferimento tecnico nazionale
A25: ISO27001 | B25: ISO/IEC 27001:2022 | C25: Sistema Gestione Sicurezza Informazioni | D25: Volontario (best practice)
A26: ISO27002 | B26: ISO/IEC 27002:2022 | C26: Controlli sicurezza informazioni | D26: Volontario (best practice)
A27: NIST | B27: NIST Cybersecurity Framework 2.0 | C27: Gestione rischio cybersecurity | D27: Volontario (best practice)
A28: CIS | B28: CIS Critical Security Controls v8 | C28: Controlli prioritari sicurezza | D28: Volontario (best practice)
A29: AgID-MM | B29: Circolare AgID 2/2017 - Misure Minime | C29: Sicurezza ICT per PA | D29: Obbligatorio per tutte le PA
A30: GDPR | B30: Regolamento (UE) 2016/679 | C30: Protezione dati personali | D30: Obbligatorio
A31: CAD | B31: D.Lgs. 82/2005 - Codice Amministrazione Digitale | C31: Digitalizzazione PA | D31: Obbligatorio per PA
A32: PSNC | B32: DL 105/2019 - Perimetro Sicurezza Nazionale | C32: Infrastrutture critiche nazionali | D32: Obbligatorio per soggetti PSNC
A36: 3. FUNZIONI DEL FRAMEWORK NAZIONALE (FNCS 2025 / NIST CSF 2.0)
A38: Codice | B38: Funzione | C38: Descrizione | D38: Focus
A39: GV | B39: GOVERN (Governare) | C39: Stabilisce la strategia, le aspettative e le politiche di gestione del rischio cyber | D39: Governance, ruoli, policy, supervisione
A40: ID | B40: IDENTIFY (Identificare) | C40: Comprensione del contesto organizzativo e degli asset da proteggere | D40: Asset, rischi, supply chain, dati
A41: PR | B41: PROTECT (Proteggere) | C41: Implementazione di misure di salvaguardia per i servizi critici | D41: Controllo accessi, awareness, sicurezza dati
A42: DE | B42: DETECT (Rilevare) | C42: Identificazione tempestiva degli eventi di sicurezza | D42: Monitoraggio, anomalie, eventi
A43: RS | B43: RESPOND (Rispondere) | C43: Azioni in risposta ad un incidente di sicurezza rilevato | D43: Gestione incidenti, comunicazione, mitigazione
A44: RC | B44: RECOVER (Ripristinare) | C44: Ripristino delle capacità e servizi compromessi | D44: Recovery planning, miglioramento, comunicazione
A47: 4. GUIDA ALLA LETTURA DELL'INDICE
A49: • PROCESSO: Area tematica di riferimento (es. Gestione del Rischio, Incident Management)
A50: • COD.DOC: Codice identificativo suggerito per il documento
A51: • TITOLO DOCUMENTO: Nome descrittivo del documento
A52: • TIPOLOGIA: Classificazione secondo la gerarchia documentale (POL, PRC, PRO, IO, etc.)
...

Sheet MAPPA COMPLETAMENTO
A1: Count of COD.DOC | B1: Column Labels
A2: Row Labels | B2: Policy | C2: Processo | D2: Procedura | E2: Linea Guida | F2: Documento | G2: Manuale | H2: Playbook | I2: Piano | J2: Registro | K2: Report | L2: Grand Total
A3: 01. GOVERNANCE E STRATEGIA | B3: 3 | C3: 1 | F3: 1 | I3: 1 | J3: 1 | K3: 1 | L3: 8
A4: 02. GESTIONE DEL RISCHIO | C4: 1 | D4: 2 | F4: 1 | I4: 1 | J4: 1 | L4: 6
A5: 03. GESTIONE DEGLI ASSET | B5: 1 | C5: 1 | D5: 2 | J5: 4 | L5: 8
A6: 04. CONTROLLO DEGLI ACCESSI | B6: 1 | C6: 1 | D6: 4 | E6: 1 | J6: 1 | L6: 8
A7: 05. PROTEZIONE DEI DATI | B7: 2 | C7: 1 | D7: 4 | J7: 1 | L7: 8
A8: 06. SICUREZZA DELLE RETI | B8: 1 | C8: 1 | D8: 4 | F8: 1 | J8: 1 | L8: 8
A9: 07. SICUREZZA ENDPOINT | B9: 1 | C9: 1 | D9: 3 | E9: 2 | L9: 7
A10: 08. GESTIONE VULNERABILITÀ | C10: 1 | D10: 4 | J10: 1 | L10: 6
A11: 09. CHANGE MANAGEMENT | C11: 1 | D11: 2 | J11: 1 | L11: 4
A12: 10. SICUREZZA APPLICATIVA | B12: 1 | C12: 1 | D12: 3 | E12: 2 | L12: 7
A13: 11. SICUREZZA FISICA | B13: 1 | D13: 3 | J13: 1 | L13: 5
A14: 12. MONITORAGGIO E DETECTION | B14: 1 | C14: 1 | D14: 4 | E14: 1 | G14: 1 | L14: 8
A15: 13. INCIDENT MANAGEMENT | B15: 1 | C15: 1 | D15: 5 | H15: 5 | J15: 1 | L15: 13
A16: 14. CONTINUITÀ OPERATIVA | B16: 1 | C16: 1 | D16: 3 | F16: 1 | I16: 3 | L16: 9
A17: 15. THREAT INTELLIGENCE | C17: 1 | D17: 2 | J17: 1 | L17: 4
A18: 16. FORMAZIONE E AWARENESS | B18: 1 | C18: 1 | D18: 1 | I18: 1 | J18: 1 | L18: 5
A19: 17. GESTIONE FORNITORI | C19: 1 | D19: 3 | F19: 1 | J19: 1 | L19: 6
A20: 18. COMPLIANCE E AUDIT | C20: 2 | D20: 2 | I20: 1 | J20: 2 | K20: 1 | L20: 8
A21: 19. RISORSE UMANE | B21: 1 | D21: 3 | L21: 4
A22: 20. MIGLIORAMENTO CONTINUO | C22: 1 | D22: 2 | J22: 1 | K22: 1 | L22: 5
A23: Grand Total | B23: 16 | C23: 19 | D23: 56 | E23: 6 | F23: 5 | G23: 1 | H23: 5 | I23: 7 | J23: 19 | K23: 3 | L23: 137

Sheet INDICE DOCUMENTALE
A1: PROCESSO | B1: COD.DOC | C1: TITOLO DOCUMENTO | D1: TIPOLOGIA | E1: ORDINE | F1: FUNZIONE FNCS | G1: NOTE | H1: REQUISITI E FONTI | I1: PRIORITÀ | J1: STATO | K1: Link
A2: 01. GOVERNANCE E STRATEGIA | B2: POL-001 | C2: Policy di Sicurezza delle Informazioni | D2: Policy | E2: =INDEX(LEGENDA!$A$5:$B$15,MATCH(D2,LEGENDA!$B$5:$B$15,0),1) -> 1 | F2: GV | G2: Documento apicale che definisce principi e obiettivi di sicurezza. Approvazione organi direttivi | H2: ISO27001:5.2, A.5.1 | NIS2:Art.20 | L90/2024:Art.8 | ACN-DET:GV.OC-01 | FNCS:GV.PO | I2: ALTA
A3: 01. GOVERNANCE E STRATEGIA | B3: POL-002 | C3: Politica di Gestione del Rischio Cyber | D3: Policy | E3: =INDEX(LEGENDA!$A$5:$B$15,MATCH(D3,LEGENDA!$B$5:$B$15,0),1) -> 1 | F3: GV | G3: Definisce approccio, criteri e tolleranza al rischio dell'organizzazione | H3: ISO27001:6.1.2 | NIS2:Art.21 | FNCS:GV.RM | ACN-DET:GV.RM-01 | NIST:GV.RM | I3: ALTA
A4: 01. GOVERNANCE E STRATEGIA | B4: POL-003 | C4: Politica di Sicurezza della Supply Chain | D4: Policy | E4: =INDEX(LEGENDA!$A$5:$B$15,MATCH(D4,LEGENDA!$B$5:$B$15,0),1) -> 1 | F4: GV/ID | G4: Requisiti di sicurezza per fornitori e terze parti | H4: ISO27001:A.5.19-5.23 | NIS2:Art.21(2)(d) | FNCS:GV.SC | ACN-DET:ID.SC-01 | I4: ALTA
A5: 01. GOVERNANCE E STRATEGIA | B5: DOC-001 | C5: Documento Ruoli e Organizzazione Sicurezza | D5: Documento | E5: =INDEX(LEGENDA!$A$5:$B$15,MATCH(D5,LEGENDA!$B$5:$B$15,0),1) -> #N/A | F5: GV | G5: Organigramma, ruoli, responsabilità e deleghe per la sicurezza | H5: ISO27001:5.3 | L90/2024:Art.8(c) | NIS2:Art.20 | ACN-DET:GV.RR-01 | FNCS:GV.RR | I5: ALTA
A6: 01. GOVERNANCE E STRATEGIA | B6: REG-001 | C6: Registro degli Stakeholder Sicurezza | D6: Registro | E6: =INDEX(LEGENDA!$A$5:$B$15,MATCH(D6,LEGENDA!$B$5:$B$15,0),1) -> 9 | F6: GV | G6: Elenco parti interessate interne/esterne e relative aspettative | H6: ISO27001:4.2 | FNCS:GV.OC-02 | I6: MEDIA
A7: 01. GOVERNANCE E STRATEGIA | B7: PIA-001 | C7: Piano Programmatico Sicurezza ICT | D7: Piano | E7: =INDEX(LEGENDA!$A$5:$B$15,MATCH(D7,LEGENDA!$B$5:$B$15,0),1) -> 8 | F7: GV | G7: Piano pluriennale sicurezza dati, sistemi e infrastrutture | H7: L90/2024:Art.8(d) | NIS2:Art.21 | FNCS:GV.PO | ACN-DET:GV.PO-01 | I7: ALTA
A8: 01. GOVERNANCE E STRATEGIA | B8: PRC-001 | C8: Processo di Governance della Sicurezza | D8: Processo | E8: =INDEX(LEGENDA!$A$5:$B$15,MATCH(D8,LEGENDA!$B$5:$B$15,0),1) -> 2 | F8: GV | G8: Comitato sicurezza, riunioni, escalation, reporting direzionale | H8: ISO27001:5.1 | NIS2:Art.20 | FNCS:GV.OV | I8: ALTA
A9: 01. GOVERNANCE E STRATEGIA | B9: REP-001 | C9: Report Periodico alla Direzione | D9: Report | E9: =INDEX(LEGENDA!$A$5:$B$15,MATCH(D9,LEGENDA!$B$5:$B$15,0),1) -> 10 | F9: GV | G9: Report su stato sicurezza, KPI, incidenti, rischi per organi direttivi | H9: ISO27001:9.3 | NIS2:Art.20(2) | FNCS:GV.OV-02 | I9: ALTA
A10: 02. GESTIONE DEL RISCHIO | B10: PRC-002 | C10: Processo di Risk Assessment | D10: Processo | E10: =INDEX(LEGENDA!$A$5:$B$15,MATCH(D10,LEGENDA!$B$5:$B$15,0),1) -> 2 | F10: ID | G10: Metodologia identificazione, analisi e valutazione rischi cyber | H10: ISO27001:6.1.2, 8.2 | NIS2:Art.21 | FNCS:ID.RA | ACN-DET:ID.RA-01 | AgID-MM:4 | I10: ALTA
A11: 02. GESTIONE DEL RISCHIO | B11: PRO-001 | C11: Procedura di Analisi del Rischio | D11: Procedura | E11: =INDEX(LEGENDA!$A$5:$B$15,MATCH(D11,LEGENDA!$B$5:$B$15,0),1) -> 3 | F11: ID | G11: Modalità operative per conduzione risk assessment | H11: ISO27001:6.1.2 | NIS2:Art.21(2)(a) | FNCS:ID.RA | NIST:ID.RA | I11: ALTA
A12: 02. GESTIONE DEL RISCHIO | B12: REG-002 | C12: Registro dei Rischi Cyber | D12: Registro | E12: =INDEX(LEGENDA!$A$5:$B$15,MATCH(D12,LEGENDA!$B$5:$B$15,0),1) -> 9 | F12: ID | G12: Catalogo rischi identificati con impatto, probabilità, trattamento | H12: ISO27001:6.1.2 | NIS2:Art.21 | FNCS:ID.RA-05 | ACN-DET:ID.RA-02 | I12: ALTA
A13: 02. GESTIONE DEL RISCHIO | B13: PIA-002 | C13: Piano di Trattamento del Rischio | D13: Piano | E13: =INDEX(LEGENDA!$A$5:$B$15,MATCH(D13,LEGENDA!$B$5:$B$15,0),1) -> 8 | F13: ID | G13: Azioni di mitigazione, responsabili, tempistiche, risorse | H13: ISO27001:6.1.3, 6.2 | NIS2:Art.21 | FNCS:ID.RA-06 | ACN-DET:ID.RA-03 | I13: ALTA
... A138: 20. MIGLIORAMENTO CONTINUO | B138: REG-019 | C138: Registro Obiettivi Sicurezza | D138: Registro | E138: =INDEX(LEGENDA!$A$5:$B$15,MATCH(D138,LEGENDA!$B$5:$B$15,0),1) -> 9 | F138: GV | G138: Target, stato avanzamento, responsabili | H138: ISO27001:6.2 | FNCS:GV.OC-03 | ACN-DET:GV.OC-04 | I138: MEDIA

Sheet MAPPATURA FONTI
A1: FONTE NORMATIVA | B1: RIFERIMENTO | C1: AREA/REQUISITO | D1: DOCUMENTI CORRELATI
A2: NIS2 | B2: Art. 20 | C2: Governance organi direttivi | D2: POL-001, DOC-001, PRC-001, REP-001
A3: NIS2 | B3: Art. 21(2)(a) | C3: Politiche analisi rischi e sicurezza | D3: POL-002, PRC-002, PRO-001, REG-002
A4: NIS2 | B4: Art. 21(2)(b) | C4: Gestione incidenti | D4: POL-013, PRC-012, PRO-036-040, PLB-001-005
A5: NIS2 | B5: Art. 21(2)(c) | C5: Continuità operativa e disaster recovery | D5: POL-014, PIA-003, PIA-004, PRO-011, PRO-041-042
A6: NIS2 | B6: Art. 21(2)(d) | C6: Sicurezza supply chain | D6: POL-003, PRC-016, PRO-047-049, REG-016
A7: NIS2 | B7: Art. 21(2)(e) | C7: Sicurezza acquisizione, sviluppo, manutenzione | D7: POL-010, PRC-010, PRO-022-023, PRO-026-028
A8: NIS2 | B8: Art. 21(2)(f) | C8: Valutazione efficacia misure | D8: PRC-017, PIA-007, PRO-050-051
A9: NIS2 | B9: Art. 21(2)(g) | C9: Pratiche igiene informatica e formazione | D9: POL-015, PRC-015, PIA-006, PRO-046
A10: NIS2 | B10: Art. 21(2)(h) | C10: Politiche crittografia | D10: POL-007, PRC-005, PRO-009-010
A11: NIS2 | B11: Art. 21(2)(i) | C11: Sicurezza risorse umane e controllo accessi | D11: POL-005, POL-016, PRC-004, PRO-005-008, PRO-052-053
A12: NIS2 | B12: Art. 21(2)(j) | C12: Autenticazione multi-fattore | D12: LG-001, PRO-008
... A68: FNCS 2025 | B68: RC - Recover | C68: Ripristino | D68: POL-014, PIA-003-005, PRO-041-043

Sheet STATISTICHE
A1: RIEPILOGO DOCUMENTALE
A3: Tipologia | B3: Quantità | C3: Percentuale
A4: Policy (POL) | B4: 16 | C4: 11.7%
A5: Processo (PRC) | B5: 19 | C5: 13.9%
A6: Procedura (PRO) | B6: 56 | C6: 40.9%
A7: Linea Guida (LG) | B7: 6 | C7: 4.4%
A8: Istruzione Operativa (IO) | B8: 0
A9: Manuale (MAN) | B9: 1 | C9: 0.7%
A10: Playbook (PLB) | B10: 5 | C10: 3.6%
A11: Piano (PIA) | B11: 7 | C11: 5.1%
A12: Registro (REG) | B12: 19 | C12: 13.9%
A13: Report (REP) | B13: 3 | C13: 2.2%
A14: Documento (DOC) | B14: 5 | C14: 3.6%
A16: TOTALE DOCUMENTI | B16: 137 | C16: 100%
A20: DISTRIBUZIONE PER FUNZIONE FNCS
A22: Funzione | B22: Documenti
A23: GV - Govern | B23: 38
A24: ID - Identify | B24: 25
A25: PR - Protect | B25: 52
A26: DE - Detect | B26: 12
A27: RS - Respond | B27: 18
A28: RC - Recover | B28: 10
A32: DISTRIBUZIONE PER PRIORITÀ
A34: Priorità | B34: Documenti | C34: Note
A35: ALTA | B35: 98 | C35: Obbligatori per conformità normativa
A36: MEDIA | B36: 34 | C36: Raccomandati per best practice
A37: BASSA | B37: 5 | C37: Per maturità avanzata
